2023-12-12 16:52:02,959] [INFO] file=/usr/lib/python3/dist-packages/pywps/app/Service.py line=310 module=Service function=call Request: getcapabilities
2023-12-12 16:52:36,443] [INFO] file=/usr/lib/python3/dist-packages/pywps/app/Service.py line=310 module=Service function=call Request: describeprocess
2023-12-12 16:53:21,064] [INFO] file=/usr/lib/python3/dist-packages/pywps/app/Service.py line=310 module=Service function=call Request: execute
2023-12-12 16:53:21,266] [INFO] file=/usr/lib/python3/dist-packages/pywps/app/Process.py line=326 module=Process function=clean Removing temporary working directory: /home/user/OpenSource/LatinGIS/Backend/pywps-flask/workdir/pywps_process_l_31_8i9
2023-12-12 16:53:40,763] [INFO] file=/usr/lib/python3/dist-packages/pywps/app/Service.py line=310 module=Service function=call Request: execute
2023-12-12 16:53:40,908] [INFO] file=/usr/lib/python3/dist-packages/pywps/app/Process.py line=326 module=Process function=clean Removing temporary working directory: /home/user/OpenSource/LatinGIS/Backend/pywps-flask/workdir/pywps_process_z4lejp_i
2023-12-12 16:54:21,105] [INFO] file=/usr/lib/python3/dist-packages/pywps/app/Service.py line=310 module=Service function=call Request: execute
2023-12-12 16:54:21,204] [INFO] file=/usr/lib/python3/dist-packages/pywps/app/Process.py line=326 module=Process function=clean Removing temporary working directory: /home/user/OpenSource/LatinGIS/Backend/pywps-flask/workdir/pywps_process_bs8zzxhn
2023-12-12 16:54:40,652] [ERROR] file=/usr/lib/python3/dist-packages/pywps/exceptions.py line=45 module=exceptions function=__init__ Exception: code: 400, description: Document is empty, line 1, column 1, locator: 
Traceback (most recent call last):
  File "/usr/lib/python3/dist-packages/pywps/app/WPSRequest.py", line 88, in _post_request
    doc = lxml.etree.fromstring(self.http_request.get_data())
  File "src/lxml/etree.pyx", line 3235, in lxml.etree.fromstring
  File "src/lxml/parser.pxi", line 1876, in lxml.etree._parseMemoryDocument
  File "src/lxml/parser.pxi", line 1764, in lxml.etree._parseDoc
  File "src/lxml/parser.pxi", line 1127, in lxml.etree._BaseParser._parseDoc
  File "src/lxml/parser.pxi", line 601, in lxml.etree._ParserContext._handleParseResultDoc
  File "src/lxml/parser.pxi", line 711, in lxml.etree._handleParseResult
  File "src/lxml/parser.pxi", line 640, in lxml.etree._raiseParseError
  File "<string>", line 1
lxml.etree.XMLSyntaxError: Document is empty, line 1, column 1
2023-12-12 16:54:46,498] [INFO] file=/usr/lib/python3/dist-packages/pywps/app/Service.py line=310 module=Service function=call Request: execute
2023-12-12 16:54:46,623] [INFO] file=/usr/lib/python3/dist-packages/pywps/app/Process.py line=326 module=Process function=clean Removing temporary working directory: /home/user/OpenSource/LatinGIS/Backend/pywps-flask/workdir/pywps_process_w63w6ep9
2023-12-12 17:00:30,794] [INFO] file=/usr/lib/python3/dist-packages/pywps/app/Service.py line=310 module=Service function=call Request: execute
2023-12-12 17:00:30,899] [INFO] file=/usr/lib/python3/dist-packages/pywps/app/Process.py line=326 module=Process function=clean Removing temporary working directory: /home/user/OpenSource/LatinGIS/Backend/pywps-flask/workdir/pywps_process_lgty06ih
2023-12-12 17:01:03,240] [INFO] file=/usr/lib/python3/dist-packages/pywps/app/Service.py line=310 module=Service function=call Request: execute
2023-12-12 17:01:03,344] [INFO] file=/usr/lib/python3/dist-packages/pywps/app/Process.py line=326 module=Process function=clean Removing temporary working directory: /home/user/OpenSource/LatinGIS/Backend/pywps-flask/workdir/pywps_process_1c9rk3fg
2023-12-12 17:01:16,213] [INFO] file=/usr/lib/python3/dist-packages/pywps/app/Service.py line=310 module=Service function=call Request: execute
2023-12-12 17:01:16,346] [INFO] file=/usr/lib/python3/dist-packages/pywps/app/Process.py line=326 module=Process function=clean Removing temporary working directory: /home/user/OpenSource/LatinGIS/Backend/pywps-flask/workdir/pywps_process_9c19yld8
2023-12-12 17:01:25,546] [INFO] file=/usr/lib/python3/dist-packages/pywps/app/Service.py line=310 module=Service function=call Request: execute
2023-12-12 17:01:25,658] [INFO] file=/usr/lib/python3/dist-packages/pywps/app/Process.py line=326 module=Process function=clean Removing temporary working directory: /home/user/OpenSource/LatinGIS/Backend/pywps-flask/workdir/pywps_process_2bbxzdpc
2023-12-12 17:01:47,713] [INFO] file=/usr/lib/python3/dist-packages/pywps/app/Service.py line=310 module=Service function=call Request: execute
2023-12-12 17:01:48,398] [INFO] file=/usr/lib/python3/dist-packages/pywps/app/Process.py line=326 module=Process function=clean Removing temporary working directory: /home/user/OpenSource/LatinGIS/Backend/pywps-flask/workdir/pywps_process_qavbv84p
2023-12-12 17:02:22,306] [INFO] file=/usr/lib/python3/dist-packages/pywps/app/Service.py line=310 module=Service function=call Request: execute
2023-12-12 17:02:22,538] [INFO] file=/usr/lib/python3/dist-packages/pywps/app/Process.py line=326 module=Process function=clean Removing temporary working directory: /home/user/OpenSource/LatinGIS/Backend/pywps-flask/workdir/pywps_process_ol_3_ihc
2023-12-12 17:03:06,020] [INFO] file=/usr/lib/python3/dist-packages/pywps/app/Service.py line=310 module=Service function=call Request: describeprocess
2023-12-12 17:03:48,513] [INFO] file=/usr/lib/python3/dist-packages/pywps/app/Service.py line=310 module=Service function=call Request: describeprocess
2023-12-12 17:03:58,162] [INFO] file=/usr/lib/python3/dist-packages/pywps/app/Service.py line=310 module=Service function=call Request: describeprocess
2023-12-12 17:04:53,040] [INFO] file=/usr/lib/python3/dist-packages/pywps/app/Service.py line=310 module=Service function=call Request: describeprocess
2023-12-12 17:04:58,626] [INFO] file=/usr/lib/python3/dist-packages/pywps/app/Service.py line=310 module=Service function=call Request: describeprocess
2023-12-12 17:12:25,854] [INFO] file=/usr/lib/python3/dist-packages/pywps/app/Service.py line=310 module=Service function=call Request: execute
2023-12-12 17:12:25,997] [INFO] file=/usr/lib/python3/dist-packages/pywps/app/Process.py line=326 module=Process function=clean Removing temporary working directory: /home/user/OpenSource/LatinGIS/Backend/pywps-flask/workdir/pywps_process_jvcrlg2z
2023-12-12 17:23:12,781] [INFO] file=/usr/lib/python3/dist-packages/pywps/app/Service.py line=310 module=Service function=call Request: describeprocess
2023-12-12 17:25:00,755] [INFO] file=/usr/lib/python3/dist-packages/pywps/app/Service.py line=310 module=Service function=call Request: describeprocess
2023-12-12 17:25:00,821] [ERROR] file=/usr/lib/python3/dist-packages/pywps/exceptions.py line=45 module=exceptions function=__init__ Exception: code: 400, description: Unknown process BufferProcess, locator: identifier
NoneType: None
2023-12-12 17:31:31,264] [INFO] file=/usr/lib/python3/dist-packages/pywps/app/Service.py line=310 module=Service function=call Request: describeprocess
2023-12-12 17:31:31,330] [ERROR] file=/usr/lib/python3/dist-packages/pywps/exceptions.py line=45 module=exceptions function=__init__ Exception: code: 400, description: Unknown process BufferProcess, locator: identifier
NoneType: None
2023-12-12 17:31:38,637] [INFO] file=/usr/lib/python3/dist-packages/pywps/app/Service.py line=310 module=Service function=call Request: describeprocess
2023-12-12 17:31:44,537] [INFO] file=/usr/lib/python3/dist-packages/pywps/app/Service.py line=310 module=Service function=call Request: describeprocess
2023-12-12 17:31:44,584] [ERROR] file=/usr/lib/python3/dist-packages/pywps/exceptions.py line=45 module=exceptions function=__init__ Exception: code: 400, description: Unknown process buffer_json, locator: identifier
NoneType: None
2023-12-12 17:32:47,129] [INFO] file=/usr/lib/python3/dist-packages/pywps/app/Service.py line=310 module=Service function=call Request: describeprocess
2023-12-12 17:32:47,130] [ERROR] file=/usr/lib/python3/dist-packages/pywps/exceptions.py line=45 module=exceptions function=__init__ Exception: code: 500, description: No applicable error code, please check error log., locator: 
Traceback (most recent call last):
  File "/usr/lib/python3/dist-packages/sqlalchemy/engine/base.py", line 2276, in _wrap_pool_connect
    return fn()
  File "/usr/lib/python3/dist-packages/sqlalchemy/pool/base.py", line 363, in connect
    return _ConnectionFairy._checkout(self)
  File "/usr/lib/python3/dist-packages/sqlalchemy/pool/base.py", line 760, in _checkout
    fairy = _ConnectionRecord.checkout(pool)
  File "/usr/lib/python3/dist-packages/sqlalchemy/pool/base.py", line 492, in checkout
    rec = pool._do_get()
  File "/usr/lib/python3/dist-packages/sqlalchemy/pool/impl.py", line 238, in _do_get
    return self._create_connection()
  File "/usr/lib/python3/dist-packages/sqlalchemy/pool/base.py", line 308, in _create_connection
    return _ConnectionRecord(self)
  File "/usr/lib/python3/dist-packages/sqlalchemy/pool/base.py", line 437, in __init__
    self.__connect(first_connect_check=True)
  File "/usr/lib/python3/dist-packages/sqlalchemy/pool/base.py", line 639, in __connect
    connection = pool._invoke_creator(self)
  File "/usr/lib/python3/dist-packages/sqlalchemy/engine/strategies.py", line 114, in connect
    return dialect.connect(*cargs, **cparams)
  File "/usr/lib/python3/dist-packages/sqlalchemy/engine/default.py", line 482, in connect
    return self.dbapi.connect(*cargs, **cparams)
sqlite3.OperationalError: unable to open database file

The above exception was the direct cause of the following exception:

Traceback (most recent call last):
  File "/usr/lib/python3/dist-packages/pywps/app/Service.py", line 314, in call
    log_request(request_uuid, wps_request)
  File "/usr/lib/python3/dist-packages/pywps/dblog.py", line 77, in log_request
    session.commit()
  File "/usr/lib/python3/dist-packages/sqlalchemy/orm/session.py", line 1036, in commit
    self.transaction.commit()
  File "/usr/lib/python3/dist-packages/sqlalchemy/orm/session.py", line 503, in commit
    self._prepare_impl()
  File "/usr/lib/python3/dist-packages/sqlalchemy/orm/session.py", line 482, in _prepare_impl
    self.session.flush()
  File "/usr/lib/python3/dist-packages/sqlalchemy/orm/session.py", line 2479, in flush
    self._flush(objects)
  File "/usr/lib/python3/dist-packages/sqlalchemy/orm/session.py", line 2617, in _flush
    transaction.rollback(_capture_exception=True)
  File "/usr/lib/python3/dist-packages/sqlalchemy/util/langhelpers.py", line 68, in __exit__
    compat.reraise(exc_type, exc_value, exc_tb)
  File "/usr/lib/python3/dist-packages/sqlalchemy/util/compat.py", line 153, in reraise
    raise value
  File "/usr/lib/python3/dist-packages/sqlalchemy/orm/session.py", line 2577, in _flush
    flush_context.execute()
  File "/usr/lib/python3/dist-packages/sqlalchemy/orm/unitofwork.py", line 422, in execute
    rec.execute(self)
  File "/usr/lib/python3/dist-packages/sqlalchemy/orm/unitofwork.py", line 586, in execute
    persistence.save_obj(
  File "/usr/lib/python3/dist-packages/sqlalchemy/orm/persistence.py", line 205, in save_obj
    for (
  File "/usr/lib/python3/dist-packages/sqlalchemy/orm/persistence.py", line 373, in _organize_states_for_save
    for state, dict_, mapper, connection in _connections_for_states(
  File "/usr/lib/python3/dist-packages/sqlalchemy/orm/persistence.py", line 1604, in _connections_for_states
    connection = uowtransaction.transaction.connection(base_mapper)
  File "/usr/lib/python3/dist-packages/sqlalchemy/orm/session.py", line 313, in connection
    return self._connection_for_bind(bind, execution_options)
  File "/usr/lib/python3/dist-packages/sqlalchemy/orm/session.py", line 420, in _connection_for_bind
    conn = self._parent._connection_for_bind(bind, execution_options)
  File "/usr/lib/python3/dist-packages/sqlalchemy/orm/session.py", line 432, in _connection_for_bind
    conn = bind._contextual_connect()
  File "/usr/lib/python3/dist-packages/sqlalchemy/engine/base.py", line 2242, in _contextual_connect
    self._wrap_pool_connect(self.pool.connect, None),
  File "/usr/lib/python3/dist-packages/sqlalchemy/engine/base.py", line 2279, in _wrap_pool_connect
    Connection._handle_dbapi_exception_noconnection(
  File "/usr/lib/python3/dist-packages/sqlalchemy/engine/base.py", line 1547, in _handle_dbapi_exception_noconnection
    util.raise_from_cause(sqlalchemy_exception, exc_info)
  File "/usr/lib/python3/dist-packages/sqlalchemy/util/compat.py", line 398, in raise_from_cause
    reraise(type(exception), exception, tb=exc_tb, cause=cause)
  File "/usr/lib/python3/dist-packages/sqlalchemy/util/compat.py", line 152, in reraise
    raise value.with_traceback(tb)
  File "/usr/lib/python3/dist-packages/sqlalchemy/engine/base.py", line 2276, in _wrap_pool_connect
    return fn()
  File "/usr/lib/python3/dist-packages/sqlalchemy/pool/base.py", line 363, in connect
    return _ConnectionFairy._checkout(self)
  File "/usr/lib/python3/dist-packages/sqlalchemy/pool/base.py", line 760, in _checkout
    fairy = _ConnectionRecord.checkout(pool)
  File "/usr/lib/python3/dist-packages/sqlalchemy/pool/base.py", line 492, in checkout
    rec = pool._do_get()
  File "/usr/lib/python3/dist-packages/sqlalchemy/pool/impl.py", line 238, in _do_get
    return self._create_connection()
  File "/usr/lib/python3/dist-packages/sqlalchemy/pool/base.py", line 308, in _create_connection
    return _ConnectionRecord(self)
  File "/usr/lib/python3/dist-packages/sqlalchemy/pool/base.py", line 437, in __init__
    self.__connect(first_connect_check=True)
  File "/usr/lib/python3/dist-packages/sqlalchemy/pool/base.py", line 639, in __connect
    connection = pool._invoke_creator(self)
  File "/usr/lib/python3/dist-packages/sqlalchemy/engine/strategies.py", line 114, in connect
    return dialect.connect(*cargs, **cparams)
  File "/usr/lib/python3/dist-packages/sqlalchemy/engine/default.py", line 482, in connect
    return self.dbapi.connect(*cargs, **cparams)
sqlalchemy.exc.OperationalError: (sqlite3.OperationalError) unable to open database file
(Background on this error at: http://sqlalche.me/e/e3q8)
2023-12-12 17:38:22,830] [INFO] file=/usr/lib/python3/dist-packages/pywps/app/Service.py line=310 module=Service function=call Request: execute
2023-12-12 17:38:22,830] [ERROR] file=/usr/lib/python3/dist-packages/pywps/exceptions.py line=45 module=exceptions function=__init__ Exception: code: 500, description: No applicable error code, please check error log., locator: 
Traceback (most recent call last):
  File "/usr/lib/python3/dist-packages/sqlalchemy/engine/base.py", line 2276, in _wrap_pool_connect
    return fn()
  File "/usr/lib/python3/dist-packages/sqlalchemy/pool/base.py", line 363, in connect
    return _ConnectionFairy._checkout(self)
  File "/usr/lib/python3/dist-packages/sqlalchemy/pool/base.py", line 760, in _checkout
    fairy = _ConnectionRecord.checkout(pool)
  File "/usr/lib/python3/dist-packages/sqlalchemy/pool/base.py", line 492, in checkout
    rec = pool._do_get()
  File "/usr/lib/python3/dist-packages/sqlalchemy/pool/impl.py", line 238, in _do_get
    return self._create_connection()
  File "/usr/lib/python3/dist-packages/sqlalchemy/pool/base.py", line 308, in _create_connection
    return _ConnectionRecord(self)
  File "/usr/lib/python3/dist-packages/sqlalchemy/pool/base.py", line 437, in __init__
    self.__connect(first_connect_check=True)
  File "/usr/lib/python3/dist-packages/sqlalchemy/pool/base.py", line 639, in __connect
    connection = pool._invoke_creator(self)
  File "/usr/lib/python3/dist-packages/sqlalchemy/engine/strategies.py", line 114, in connect
    return dialect.connect(*cargs, **cparams)
  File "/usr/lib/python3/dist-packages/sqlalchemy/engine/default.py", line 482, in connect
    return self.dbapi.connect(*cargs, **cparams)
sqlite3.OperationalError: unable to open database file

The above exception was the direct cause of the following exception:

Traceback (most recent call last):
  File "/usr/lib/python3/dist-packages/pywps/app/Service.py", line 314, in call
    log_request(request_uuid, wps_request)
  File "/usr/lib/python3/dist-packages/pywps/dblog.py", line 77, in log_request
    session.commit()
  File "/usr/lib/python3/dist-packages/sqlalchemy/orm/session.py", line 1036, in commit
    self.transaction.commit()
  File "/usr/lib/python3/dist-packages/sqlalchemy/orm/session.py", line 503, in commit
    self._prepare_impl()
  File "/usr/lib/python3/dist-packages/sqlalchemy/orm/session.py", line 482, in _prepare_impl
    self.session.flush()
  File "/usr/lib/python3/dist-packages/sqlalchemy/orm/session.py", line 2479, in flush
    self._flush(objects)
  File "/usr/lib/python3/dist-packages/sqlalchemy/orm/session.py", line 2617, in _flush
    transaction.rollback(_capture_exception=True)
  File "/usr/lib/python3/dist-packages/sqlalchemy/util/langhelpers.py", line 68, in __exit__
    compat.reraise(exc_type, exc_value, exc_tb)
  File "/usr/lib/python3/dist-packages/sqlalchemy/util/compat.py", line 153, in reraise
    raise value
  File "/usr/lib/python3/dist-packages/sqlalchemy/orm/session.py", line 2577, in _flush
    flush_context.execute()
  File "/usr/lib/python3/dist-packages/sqlalchemy/orm/unitofwork.py", line 422, in execute
    rec.execute(self)
  File "/usr/lib/python3/dist-packages/sqlalchemy/orm/unitofwork.py", line 586, in execute
    persistence.save_obj(
  File "/usr/lib/python3/dist-packages/sqlalchemy/orm/persistence.py", line 205, in save_obj
    for (
  File "/usr/lib/python3/dist-packages/sqlalchemy/orm/persistence.py", line 373, in _organize_states_for_save
    for state, dict_, mapper, connection in _connections_for_states(
  File "/usr/lib/python3/dist-packages/sqlalchemy/orm/persistence.py", line 1604, in _connections_for_states
    connection = uowtransaction.transaction.connection(base_mapper)
  File "/usr/lib/python3/dist-packages/sqlalchemy/orm/session.py", line 313, in connection
    return self._connection_for_bind(bind, execution_options)
  File "/usr/lib/python3/dist-packages/sqlalchemy/orm/session.py", line 420, in _connection_for_bind
    conn = self._parent._connection_for_bind(bind, execution_options)
  File "/usr/lib/python3/dist-packages/sqlalchemy/orm/session.py", line 432, in _connection_for_bind
    conn = bind._contextual_connect()
  File "/usr/lib/python3/dist-packages/sqlalchemy/engine/base.py", line 2242, in _contextual_connect
    self._wrap_pool_connect(self.pool.connect, None),
  File "/usr/lib/python3/dist-packages/sqlalchemy/engine/base.py", line 2279, in _wrap_pool_connect
    Connection._handle_dbapi_exception_noconnection(
  File "/usr/lib/python3/dist-packages/sqlalchemy/engine/base.py", line 1547, in _handle_dbapi_exception_noconnection
    util.raise_from_cause(sqlalchemy_exception, exc_info)
  File "/usr/lib/python3/dist-packages/sqlalchemy/util/compat.py", line 398, in raise_from_cause
    reraise(type(exception), exception, tb=exc_tb, cause=cause)
  File "/usr/lib/python3/dist-packages/sqlalchemy/util/compat.py", line 152, in reraise
    raise value.with_traceback(tb)
  File "/usr/lib/python3/dist-packages/sqlalchemy/engine/base.py", line 2276, in _wrap_pool_connect
    return fn()
  File "/usr/lib/python3/dist-packages/sqlalchemy/pool/base.py", line 363, in connect
    return _ConnectionFairy._checkout(self)
  File "/usr/lib/python3/dist-packages/sqlalchemy/pool/base.py", line 760, in _checkout
    fairy = _ConnectionRecord.checkout(pool)
  File "/usr/lib/python3/dist-packages/sqlalchemy/pool/base.py", line 492, in checkout
    rec = pool._do_get()
  File "/usr/lib/python3/dist-packages/sqlalchemy/pool/impl.py", line 238, in _do_get
    return self._create_connection()
  File "/usr/lib/python3/dist-packages/sqlalchemy/pool/base.py", line 308, in _create_connection
    return _ConnectionRecord(self)
  File "/usr/lib/python3/dist-packages/sqlalchemy/pool/base.py", line 437, in __init__
    self.__connect(first_connect_check=True)
  File "/usr/lib/python3/dist-packages/sqlalchemy/pool/base.py", line 639, in __connect
    connection = pool._invoke_creator(self)
  File "/usr/lib/python3/dist-packages/sqlalchemy/engine/strategies.py", line 114, in connect
    return dialect.connect(*cargs, **cparams)
  File "/usr/lib/python3/dist-packages/sqlalchemy/engine/default.py", line 482, in connect
    return self.dbapi.connect(*cargs, **cparams)
sqlalchemy.exc.OperationalError: (sqlite3.OperationalError) unable to open database file
(Background on this error at: http://sqlalche.me/e/e3q8)
2023-12-12 17:38:36,078] [INFO] file=/usr/lib/python3/dist-packages/pywps/app/Service.py line=310 module=Service function=call Request: execute
2023-12-12 17:38:36,079] [ERROR] file=/usr/lib/python3/dist-packages/pywps/exceptions.py line=45 module=exceptions function=__init__ Exception: code: 500, description: No applicable error code, please check error log., locator: 
Traceback (most recent call last):
  File "/usr/lib/python3/dist-packages/sqlalchemy/engine/base.py", line 2276, in _wrap_pool_connect
    return fn()
  File "/usr/lib/python3/dist-packages/sqlalchemy/pool/base.py", line 363, in connect
    return _ConnectionFairy._checkout(self)
  File "/usr/lib/python3/dist-packages/sqlalchemy/pool/base.py", line 760, in _checkout
    fairy = _ConnectionRecord.checkout(pool)
  File "/usr/lib/python3/dist-packages/sqlalchemy/pool/base.py", line 492, in checkout
    rec = pool._do_get()
  File "/usr/lib/python3/dist-packages/sqlalchemy/pool/impl.py", line 238, in _do_get
    return self._create_connection()
  File "/usr/lib/python3/dist-packages/sqlalchemy/pool/base.py", line 308, in _create_connection
    return _ConnectionRecord(self)
  File "/usr/lib/python3/dist-packages/sqlalchemy/pool/base.py", line 437, in __init__
    self.__connect(first_connect_check=True)
  File "/usr/lib/python3/dist-packages/sqlalchemy/pool/base.py", line 639, in __connect
    connection = pool._invoke_creator(self)
  File "/usr/lib/python3/dist-packages/sqlalchemy/engine/strategies.py", line 114, in connect
    return dialect.connect(*cargs, **cparams)
  File "/usr/lib/python3/dist-packages/sqlalchemy/engine/default.py", line 482, in connect
    return self.dbapi.connect(*cargs, **cparams)
sqlite3.OperationalError: unable to open database file

The above exception was the direct cause of the following exception:

Traceback (most recent call last):
  File "/usr/lib/python3/dist-packages/pywps/app/Service.py", line 314, in call
    log_request(request_uuid, wps_request)
  File "/usr/lib/python3/dist-packages/pywps/dblog.py", line 77, in log_request
    session.commit()
  File "/usr/lib/python3/dist-packages/sqlalchemy/orm/session.py", line 1036, in commit
    self.transaction.commit()
  File "/usr/lib/python3/dist-packages/sqlalchemy/orm/session.py", line 503, in commit
    self._prepare_impl()
  File "/usr/lib/python3/dist-packages/sqlalchemy/orm/session.py", line 482, in _prepare_impl
    self.session.flush()
  File "/usr/lib/python3/dist-packages/sqlalchemy/orm/session.py", line 2479, in flush
    self._flush(objects)
  File "/usr/lib/python3/dist-packages/sqlalchemy/orm/session.py", line 2617, in _flush
    transaction.rollback(_capture_exception=True)
  File "/usr/lib/python3/dist-packages/sqlalchemy/util/langhelpers.py", line 68, in __exit__
    compat.reraise(exc_type, exc_value, exc_tb)
  File "/usr/lib/python3/dist-packages/sqlalchemy/util/compat.py", line 153, in reraise
    raise value
  File "/usr/lib/python3/dist-packages/sqlalchemy/orm/session.py", line 2577, in _flush
    flush_context.execute()
  File "/usr/lib/python3/dist-packages/sqlalchemy/orm/unitofwork.py", line 422, in execute
    rec.execute(self)
  File "/usr/lib/python3/dist-packages/sqlalchemy/orm/unitofwork.py", line 586, in execute
    persistence.save_obj(
  File "/usr/lib/python3/dist-packages/sqlalchemy/orm/persistence.py", line 205, in save_obj
    for (
  File "/usr/lib/python3/dist-packages/sqlalchemy/orm/persistence.py", line 373, in _organize_states_for_save
    for state, dict_, mapper, connection in _connections_for_states(
  File "/usr/lib/python3/dist-packages/sqlalchemy/orm/persistence.py", line 1604, in _connections_for_states
    connection = uowtransaction.transaction.connection(base_mapper)
  File "/usr/lib/python3/dist-packages/sqlalchemy/orm/session.py", line 313, in connection
    return self._connection_for_bind(bind, execution_options)
  File "/usr/lib/python3/dist-packages/sqlalchemy/orm/session.py", line 420, in _connection_for_bind
    conn = self._parent._connection_for_bind(bind, execution_options)
  File "/usr/lib/python3/dist-packages/sqlalchemy/orm/session.py", line 432, in _connection_for_bind
    conn = bind._contextual_connect()
  File "/usr/lib/python3/dist-packages/sqlalchemy/engine/base.py", line 2242, in _contextual_connect
    self._wrap_pool_connect(self.pool.connect, None),
  File "/usr/lib/python3/dist-packages/sqlalchemy/engine/base.py", line 2279, in _wrap_pool_connect
    Connection._handle_dbapi_exception_noconnection(
  File "/usr/lib/python3/dist-packages/sqlalchemy/engine/base.py", line 1547, in _handle_dbapi_exception_noconnection
    util.raise_from_cause(sqlalchemy_exception, exc_info)
  File "/usr/lib/python3/dist-packages/sqlalchemy/util/compat.py", line 398, in raise_from_cause
    reraise(type(exception), exception, tb=exc_tb, cause=cause)
  File "/usr/lib/python3/dist-packages/sqlalchemy/util/compat.py", line 152, in reraise
    raise value.with_traceback(tb)
  File "/usr/lib/python3/dist-packages/sqlalchemy/engine/base.py", line 2276, in _wrap_pool_connect
    return fn()
  File "/usr/lib/python3/dist-packages/sqlalchemy/pool/base.py", line 363, in connect
    return _ConnectionFairy._checkout(self)
  File "/usr/lib/python3/dist-packages/sqlalchemy/pool/base.py", line 760, in _checkout
    fairy = _ConnectionRecord.checkout(pool)
  File "/usr/lib/python3/dist-packages/sqlalchemy/pool/base.py", line 492, in checkout
    rec = pool._do_get()
  File "/usr/lib/python3/dist-packages/sqlalchemy/pool/impl.py", line 238, in _do_get
    return self._create_connection()
  File "/usr/lib/python3/dist-packages/sqlalchemy/pool/base.py", line 308, in _create_connection
    return _ConnectionRecord(self)
  File "/usr/lib/python3/dist-packages/sqlalchemy/pool/base.py", line 437, in __init__
    self.__connect(first_connect_check=True)
  File "/usr/lib/python3/dist-packages/sqlalchemy/pool/base.py", line 639, in __connect
    connection = pool._invoke_creator(self)
  File "/usr/lib/python3/dist-packages/sqlalchemy/engine/strategies.py", line 114, in connect
    return dialect.connect(*cargs, **cparams)
  File "/usr/lib/python3/dist-packages/sqlalchemy/engine/default.py", line 482, in connect
    return self.dbapi.connect(*cargs, **cparams)
sqlalchemy.exc.OperationalError: (sqlite3.OperationalError) unable to open database file
(Background on this error at: http://sqlalche.me/e/e3q8)
2023-12-12 17:45:53,605] [INFO] file=/usr/lib/python3/dist-packages/pywps/app/Service.py line=310 module=Service function=call Request: describeprocess
2023-12-12 17:46:09,537] [INFO] file=/usr/lib/python3/dist-packages/pywps/app/Service.py line=310 module=Service function=call Request: execute
2023-12-12 17:46:09,562] [ERROR] file=/usr/lib/python3/dist-packages/pywps/exceptions.py line=45 module=exceptions function=__init__ Exception: code: 400, description: Unknown process 'buffer_json', locator: Identifier
Traceback (most recent call last):
  File "/usr/lib/python3/dist-packages/pywps/app/Service.py", line 87, in prepare_process_for_execution
    process = self.processes[identifier]
KeyError: 'buffer_json'
2023-12-12 17:46:22,635] [INFO] file=/usr/lib/python3/dist-packages/pywps/app/Service.py line=310 module=Service function=call Request: describeprocess
2023-12-12 17:46:22,698] [ERROR] file=/usr/lib/python3/dist-packages/pywps/exceptions.py line=45 module=exceptions function=__init__ Exception: code: 400, description: Unknown process buffer_json, locator: identifier
NoneType: None
2023-12-12 17:55:34,570] [INFO] file=/usr/lib/python3/dist-packages/pywps/app/Service.py line=310 module=Service function=call Request: execute
2023-12-12 17:55:34,753] [INFO] file=/usr/lib/python3/dist-packages/pywps/app/Process.py line=326 module=Process function=clean Removing temporary working directory: /home/user/OpenSource/LatinGIS/Backend/pywps/pywps-flask/workdir/pywps_process_2z1fazsj
2023-12-12 17:56:32,631] [INFO] file=/usr/lib/python3/dist-packages/pywps/app/Service.py line=310 module=Service function=call Request: describeprocess
2023-12-12 17:57:29,672] [INFO] file=/usr/lib/python3/dist-packages/pywps/app/Service.py line=310 module=Service function=call Request: execute
2023-12-12 17:57:29,726] [ERROR] file=/usr/lib/python3/dist-packages/pywps/app/Service.py line=136 module=Service function=_parse_and_execute Missing parameter value: poly_in
2023-12-12 17:57:29,726] [ERROR] file=/usr/lib/python3/dist-packages/pywps/exceptions.py line=45 module=exceptions function=__init__ Exception: code: 400, description: poly_in, locator: poly_in
NoneType: None
2023-12-12 17:57:47,512] [INFO] file=/usr/lib/python3/dist-packages/pywps/app/Service.py line=310 module=Service function=call Request: execute
2023-12-12 17:57:47,518] [ERROR] file=/usr/lib/python3/dist-packages/pywps/app/Service.py line=136 module=Service function=_parse_and_execute Missing parameter value: name
2023-12-12 17:57:47,518] [ERROR] file=/usr/lib/python3/dist-packages/pywps/exceptions.py line=45 module=exceptions function=__init__ Exception: code: 400, description: name, locator: name
NoneType: None
2023-12-12 17:58:17,735] [INFO] file=/usr/lib/python3/dist-packages/pywps/app/Service.py line=310 module=Service function=call Request: execute
2023-12-12 17:58:17,745] [INFO] file=/usr/lib/python3/dist-packages/pywps/validator/complexvalidator.py line=46 module=complexvalidator function=validategml validating GML; Mode: 2
2023-12-12 17:58:18,152] [ERROR] file=/usr/lib/python3/dist-packages/pywps/exceptions.py line=45 module=exceptions function=__init__ Exception: code: 400, description: Input data not valid using mode 2, locator: 
NoneType: None
2023-12-12 17:58:47,929] [INFO] file=/usr/lib/python3/dist-packages/pywps/app/Service.py line=310 module=Service function=call Request: describeprocess
2023-12-12 17:58:48,001] [ERROR] file=/usr/lib/python3/dist-packages/pywps/exceptions.py line=45 module=exceptions function=__init__ Exception: code: 400, description: Unknown process buffer_json, locator: identifier
NoneType: None
2023-12-13 18:16:10,894] [INFO] file=/usr/lib/python3/dist-packages/pywps/app/Service.py line=310 module=Service function=call Request: describeprocess
2023-12-13 18:16:12,340] [INFO] file=/usr/lib/python3/dist-packages/pywps/app/Service.py line=310 module=Service function=call Request: describeprocess
2023-12-13 18:16:29,445] [INFO] file=/usr/lib/python3/dist-packages/pywps/app/Service.py line=310 module=Service function=call Request: getcapabilities
2023-12-15 10:17:56,909] [INFO] file=/usr/lib/python3/dist-packages/pywps/app/Service.py line=310 module=Service function=call Request: execute
2023-12-15 10:18:00,609] [INFO] file=/usr/lib/python3/dist-packages/pywps/app/Process.py line=326 module=Process function=clean Removing temporary working directory: /home/user/OpenSource/LatinGIS/Backend/pywps/pywps-flask/workdir/pywps_process_a1pyfx1p
2023-12-15 10:19:18,783] [INFO] file=/usr/lib/python3/dist-packages/pywps/app/Service.py line=310 module=Service function=call Request: execute
2023-12-15 10:19:18,890] [INFO] file=/usr/lib/python3/dist-packages/pywps/app/Process.py line=326 module=Process function=clean Removing temporary working directory: /home/user/OpenSource/LatinGIS/Backend/pywps/pywps-flask/workdir/pywps_process_lv89dy7o
2023-12-15 10:19:27,385] [INFO] file=/usr/lib/python3/dist-packages/pywps/app/Service.py line=310 module=Service function=call Request: execute
2023-12-15 10:19:27,538] [INFO] file=/usr/lib/python3/dist-packages/pywps/app/Process.py line=326 module=Process function=clean Removing temporary working directory: /home/user/OpenSource/LatinGIS/Backend/pywps/pywps-flask/workdir/pywps_process_r9r145kc
2023-12-15 10:19:47,491] [INFO] file=/usr/lib/python3/dist-packages/pywps/app/Service.py line=310 module=Service function=call Request: execute
2023-12-15 10:19:48,008] [INFO] file=/usr/lib/python3/dist-packages/pywps/app/Process.py line=326 module=Process function=clean Removing temporary working directory: /home/user/OpenSource/LatinGIS/Backend/pywps/pywps-flask/workdir/pywps_process_jck3co8j
2023-12-15 10:48:56,863] [INFO] file=/usr/lib/python3/dist-packages/pywps/app/Service.py line=310 module=Service function=call Request: describeprocess
2023-12-15 12:31:05,610] [INFO] file=/usr/lib/python3/dist-packages/pywps/app/Service.py line=310 module=Service function=call Request: describeprocess
2023-12-15 12:32:07,736] [INFO] file=/usr/lib/python3/dist-packages/pywps/app/Service.py line=310 module=Service function=call Request: execute
2023-12-15 12:32:07,838] [INFO] file=/usr/lib/python3/dist-packages/pywps/app/Process.py line=326 module=Process function=clean Removing temporary working directory: /home/user/OpenSource/LatinGIS/Backend/pywps/pywps-flask/workdir/pywps_process_6gas5vnw
2024-01-18 19:28:46,692] [INFO] file=/usr/lib/python3/dist-packages/pywps/app/Service.py line=310 module=Service function=call Request: getcapabilities
2024-01-18 19:29:48,453] [ERROR] file=/usr/lib/python3/dist-packages/pywps/exceptions.py line=45 module=exceptions function=__init__ Exception: code: 400, description: Missing version, locator: version
NoneType: None
2024-01-18 19:30:11,226] [WARNING] file=/usr/lib/python3/dist-packages/pywps/app/WPSRequest.py line=530 module=WPSRequest function=get_data_from_kvp not enough values to unpack (expected 2, got 1)
2024-01-18 19:30:11,226] [INFO] file=/usr/lib/python3/dist-packages/pywps/app/Service.py line=310 module=Service function=call Request: execute
2024-01-18 19:30:11,233] [ERROR] file=/usr/lib/python3/dist-packages/pywps/app/Service.py line=136 module=Service function=_parse_and_execute Missing parameter value: poly_in
2024-01-18 19:30:11,234] [ERROR] file=/usr/lib/python3/dist-packages/pywps/exceptions.py line=45 module=exceptions function=__init__ Exception: code: 400, description: poly_in, locator: poly_in
NoneType: None
2024-01-18 19:31:07,521] [WARNING] file=/usr/lib/python3/dist-packages/pywps/app/WPSRequest.py line=530 module=WPSRequest function=get_data_from_kvp too many values to unpack (expected 2)
2024-01-18 19:31:07,522] [INFO] file=/usr/lib/python3/dist-packages/pywps/app/Service.py line=310 module=Service function=call Request: execute
2024-01-18 19:31:07,627] [ERROR] file=/usr/lib/python3/dist-packages/pywps/app/Service.py line=136 module=Service function=_parse_and_execute Missing parameter value: poly_in
2024-01-18 19:31:07,627] [ERROR] file=/usr/lib/python3/dist-packages/pywps/exceptions.py line=45 module=exceptions function=__init__ Exception: code: 400, description: poly_in, locator: poly_in
NoneType: None
2024-01-18 19:32:02,142] [INFO] file=/usr/lib/python3/dist-packages/pywps/app/Service.py line=310 module=Service function=call Request: execute
2024-01-18 19:32:02,151] [ERROR] file=/usr/lib/python3/dist-packages/pywps/app/Service.py line=136 module=Service function=_parse_and_execute Missing parameter value: poly_in
2024-01-18 19:32:02,151] [ERROR] file=/usr/lib/python3/dist-packages/pywps/exceptions.py line=45 module=exceptions function=__init__ Exception: code: 400, description: poly_in, locator: poly_in
NoneType: None
2024-01-18 19:53:42,576] [INFO] file=/usr/lib/python3/dist-packages/pywps/app/Service.py line=310 module=Service function=call Request: describeprocess
2024-01-18 20:02:57,978] [WARNING] file=/usr/lib/python3/dist-packages/pywps/app/WPSRequest.py line=530 module=WPSRequest function=get_data_from_kvp too many values to unpack (expected 2)
2024-01-18 20:02:57,979] [INFO] file=/usr/lib/python3/dist-packages/pywps/app/Service.py line=310 module=Service function=call Request: execute
2024-01-18 20:02:58,018] [ERROR] file=/usr/lib/python3/dist-packages/pywps/app/Service.py line=136 module=Service function=_parse_and_execute Missing parameter value: poly_in
2024-01-18 20:02:58,019] [ERROR] file=/usr/lib/python3/dist-packages/pywps/exceptions.py line=45 module=exceptions function=__init__ Exception: code: 400, description: poly_in, locator: poly_in
NoneType: None
2024-01-18 20:03:13,122] [WARNING] file=/usr/lib/python3/dist-packages/pywps/app/WPSRequest.py line=530 module=WPSRequest function=get_data_from_kvp not enough values to unpack (expected 2, got 1)
2024-01-18 20:03:13,122] [INFO] file=/usr/lib/python3/dist-packages/pywps/app/Service.py line=310 module=Service function=call Request: execute
2024-01-18 20:03:13,137] [ERROR] file=/usr/lib/python3/dist-packages/pywps/app/Service.py line=136 module=Service function=_parse_and_execute Missing parameter value: poly_in
2024-01-18 20:03:13,137] [ERROR] file=/usr/lib/python3/dist-packages/pywps/exceptions.py line=45 module=exceptions function=__init__ Exception: code: 400, description: poly_in, locator: poly_in
NoneType: None
2024-01-18 20:03:16,024] [INFO] file=/usr/lib/python3/dist-packages/pywps/app/Service.py line=310 module=Service function=call Request: execute
2024-01-18 20:03:16,042] [ERROR] file=/usr/lib/python3/dist-packages/pywps/app/Service.py line=136 module=Service function=_parse_and_execute Missing parameter value: poly_in
2024-01-18 20:03:16,042] [ERROR] file=/usr/lib/python3/dist-packages/pywps/exceptions.py line=45 module=exceptions function=__init__ Exception: code: 400, description: poly_in, locator: poly_in
NoneType: None
2024-01-18 20:03:19,518] [WARNING] file=/usr/lib/python3/dist-packages/pywps/app/WPSRequest.py line=530 module=WPSRequest function=get_data_from_kvp not enough values to unpack (expected 2, got 1)
2024-01-18 20:03:19,518] [INFO] file=/usr/lib/python3/dist-packages/pywps/app/Service.py line=310 module=Service function=call Request: execute
2024-01-18 20:03:19,528] [ERROR] file=/usr/lib/python3/dist-packages/pywps/app/Service.py line=136 module=Service function=_parse_and_execute Missing parameter value: poly_in
2024-01-18 20:03:19,528] [ERROR] file=/usr/lib/python3/dist-packages/pywps/exceptions.py line=45 module=exceptions function=__init__ Exception: code: 400, description: poly_in, locator: poly_in
NoneType: None
2024-01-18 20:03:34,038] [INFO] file=/usr/lib/python3/dist-packages/pywps/app/Service.py line=310 module=Service function=call Request: describeprocess
2024-01-18 20:04:06,117] [INFO] file=/usr/lib/python3/dist-packages/pywps/app/Service.py line=310 module=Service function=call Request: describeprocess
2024-01-18 20:07:25,011] [INFO] file=/usr/lib/python3/dist-packages/pywps/app/Service.py line=310 module=Service function=call Request: execute
2024-01-18 20:07:25,048] [INFO] file=/usr/lib/python3/dist-packages/pywps/validator/complexvalidator.py line=46 module=complexvalidator function=validategml validating GML; Mode: 2
2024-01-18 20:07:25,600] [ERROR] file=/usr/lib/python3/dist-packages/pywps/exceptions.py line=45 module=exceptions function=__init__ Exception: code: 400, description: Input data not valid using mode 2, locator: 
NoneType: None
2024-01-18 20:11:34,982] [INFO] file=/usr/lib/python3/dist-packages/pywps/app/Service.py line=310 module=Service function=call Request: execute
2024-01-18 20:11:34,997] [INFO] file=/usr/lib/python3/dist-packages/pywps/validator/complexvalidator.py line=46 module=complexvalidator function=validategml validating GML; Mode: 2
2024-01-18 20:11:34,998] [ERROR] file=/usr/lib/python3/dist-packages/pywps/exceptions.py line=45 module=exceptions function=__init__ Exception: code: 400, description: Input data not valid using mode 2, locator: 
NoneType: None
2024-01-18 20:11:51,231] [INFO] file=/usr/lib/python3/dist-packages/pywps/app/Service.py line=310 module=Service function=call Request: execute
2024-01-18 20:11:51,245] [INFO] file=/usr/lib/python3/dist-packages/pywps/validator/complexvalidator.py line=46 module=complexvalidator function=validategml validating GML; Mode: 2
2024-01-18 20:11:51,246] [ERROR] file=/usr/lib/python3/dist-packages/pywps/exceptions.py line=45 module=exceptions function=__init__ Exception: code: 400, description: Input data not valid using mode 2, locator: 
NoneType: None
2024-01-18 22:11:42,397] [INFO] file=/usr/lib/python3/dist-packages/pywps/app/Service.py line=310 module=Service function=call Request: execute
2024-01-18 22:11:42,649] [INFO] file=/usr/lib/python3/dist-packages/pywps/validator/complexvalidator.py line=46 module=complexvalidator function=validategml validating GML; Mode: 2
2024-01-18 22:11:42,649] [ERROR] file=/usr/lib/python3/dist-packages/pywps/exceptions.py line=45 module=exceptions function=__init__ Exception: code: 400, description: Input data not valid using mode 2, locator: 
NoneType: None
2024-01-18 22:11:49,603] [INFO] file=/usr/lib/python3/dist-packages/pywps/app/Service.py line=310 module=Service function=call Request: execute
2024-01-18 22:11:49,613] [INFO] file=/usr/lib/python3/dist-packages/pywps/validator/complexvalidator.py line=46 module=complexvalidator function=validategml validating GML; Mode: 2
2024-01-18 22:11:49,614] [ERROR] file=/usr/lib/python3/dist-packages/pywps/exceptions.py line=45 module=exceptions function=__init__ Exception: code: 400, description: Input data not valid using mode 2, locator: 
NoneType: None
2024-01-18 22:11:57,035] [INFO] file=/usr/lib/python3/dist-packages/pywps/app/Service.py line=310 module=Service function=call Request: execute
2024-01-18 22:11:57,042] [INFO] file=/usr/lib/python3/dist-packages/pywps/validator/complexvalidator.py line=46 module=complexvalidator function=validategml validating GML; Mode: 2
2024-01-18 22:11:57,225] [ERROR] file=/usr/lib/python3/dist-packages/pywps/exceptions.py line=45 module=exceptions function=__init__ Exception: code: 400, description: Input data not valid using mode 2, locator: 
NoneType: None
2024-01-18 22:13:13,649] [INFO] file=/usr/lib/python3/dist-packages/pywps/app/Service.py line=310 module=Service function=call Request: execute
2024-01-18 22:13:13,666] [INFO] file=/usr/lib/python3/dist-packages/pywps/validator/complexvalidator.py line=46 module=complexvalidator function=validategml validating GML; Mode: 2
2024-01-18 22:13:13,666] [ERROR] file=/usr/lib/python3/dist-packages/pywps/exceptions.py line=45 module=exceptions function=__init__ Exception: code: 400, description: Input data not valid using mode 2, locator: 
NoneType: None
2024-01-18 22:17:20,423] [INFO] file=/usr/lib/python3/dist-packages/pywps/app/Service.py line=310 module=Service function=call Request: execute
2024-01-18 22:17:20,431] [INFO] file=/usr/lib/python3/dist-packages/pywps/validator/complexvalidator.py line=46 module=complexvalidator function=validategml validating GML; Mode: 2
2024-01-18 22:17:20,432] [ERROR] file=/usr/lib/python3/dist-packages/pywps/exceptions.py line=45 module=exceptions function=__init__ Exception: code: 400, description: Input data not valid using mode 2, locator: 
NoneType: None
2024-01-18 22:18:07,888] [INFO] file=/usr/lib/python3/dist-packages/pywps/app/Service.py line=310 module=Service function=call Request: execute
2024-01-18 22:18:07,896] [INFO] file=/usr/lib/python3/dist-packages/pywps/validator/complexvalidator.py line=46 module=complexvalidator function=validategml validating GML; Mode: 2
2024-01-18 22:18:07,896] [ERROR] file=/usr/lib/python3/dist-packages/pywps/exceptions.py line=45 module=exceptions function=__init__ Exception: code: 400, description: Input data not valid using mode 2, locator: 
NoneType: None
2024-01-18 22:33:55,823] [INFO] file=/usr/lib/python3/dist-packages/pywps/app/Service.py line=310 module=Service function=call Request: execute
2024-01-18 22:33:55,838] [INFO] file=/usr/lib/python3/dist-packages/pywps/validator/complexvalidator.py line=46 module=complexvalidator function=validategml validating GML; Mode: 2
2024-01-18 22:33:55,838] [ERROR] file=/usr/lib/python3/dist-packages/pywps/exceptions.py line=45 module=exceptions function=__init__ Exception: code: 400, description: Input data not valid using mode 2, locator: 
NoneType: None
2024-01-18 22:34:05,116] [INFO] file=/usr/lib/python3/dist-packages/pywps/app/Service.py line=310 module=Service function=call Request: execute
2024-01-18 22:34:05,125] [INFO] file=/usr/lib/python3/dist-packages/pywps/validator/complexvalidator.py line=46 module=complexvalidator function=validategml validating GML; Mode: 2
2024-01-18 22:34:05,126] [ERROR] file=/usr/lib/python3/dist-packages/pywps/exceptions.py line=45 module=exceptions function=__init__ Exception: code: 400, description: Input data not valid using mode 2, locator: 
NoneType: None
2024-01-18 22:34:12,298] [INFO] file=/usr/lib/python3/dist-packages/pywps/app/Service.py line=310 module=Service function=call Request: execute
2024-01-18 22:34:12,305] [INFO] file=/usr/lib/python3/dist-packages/pywps/validator/complexvalidator.py line=46 module=complexvalidator function=validategml validating GML; Mode: 2
2024-01-18 22:34:12,307] [ERROR] file=/usr/lib/python3/dist-packages/pywps/exceptions.py line=45 module=exceptions function=__init__ Exception: code: 400, description: Input data not valid using mode 2, locator: 
NoneType: None
2024-01-18 22:34:31,039] [INFO] file=/usr/lib/python3/dist-packages/pywps/app/Service.py line=310 module=Service function=call Request: execute
2024-01-18 22:34:31,048] [INFO] file=/usr/lib/python3/dist-packages/pywps/validator/complexvalidator.py line=46 module=complexvalidator function=validategml validating GML; Mode: 2
2024-01-18 22:34:31,048] [ERROR] file=/usr/lib/python3/dist-packages/pywps/exceptions.py line=45 module=exceptions function=__init__ Exception: code: 400, description: Input data not valid using mode 2, locator: 
NoneType: None
2024-01-18 22:35:03,599] [WARNING] file=/usr/lib/python3/dist-packages/pywps/app/WPSRequest.py line=530 module=WPSRequest function=get_data_from_kvp too many values to unpack (expected 2)
2024-01-18 22:35:03,599] [INFO] file=/usr/lib/python3/dist-packages/pywps/app/Service.py line=310 module=Service function=call Request: execute
2024-01-18 22:35:03,607] [ERROR] file=/usr/lib/python3/dist-packages/pywps/app/Service.py line=136 module=Service function=_parse_and_execute Missing parameter value: poly_in
2024-01-18 22:35:03,607] [ERROR] file=/usr/lib/python3/dist-packages/pywps/exceptions.py line=45 module=exceptions function=__init__ Exception: code: 400, description: poly_in, locator: poly_in
NoneType: None
2024-01-18 22:35:14,554] [INFO] file=/usr/lib/python3/dist-packages/pywps/app/Service.py line=310 module=Service function=call Request: execute
2024-01-18 22:35:14,562] [INFO] file=/usr/lib/python3/dist-packages/pywps/validator/complexvalidator.py line=46 module=complexvalidator function=validategml validating GML; Mode: 2
2024-01-18 22:35:14,562] [ERROR] file=/usr/lib/python3/dist-packages/pywps/exceptions.py line=45 module=exceptions function=__init__ Exception: code: 400, description: Input data not valid using mode 2, locator: 
NoneType: None
2024-01-18 23:09:01,819] [INFO] file=/usr/lib/python3/dist-packages/pywps/app/Service.py line=310 module=Service function=call Request: execute
2024-01-18 23:09:02,348] [INFO] file=/usr/lib/python3/dist-packages/pywps/validator/complexvalidator.py line=46 module=complexvalidator function=validategml validating GML; Mode: 2
2024-01-18 23:09:02,363] [ERROR] file=/usr/lib/python3/dist-packages/pywps/exceptions.py line=45 module=exceptions function=__init__ Exception: code: 400, description: Input data not valid using mode 2, locator: 
NoneType: None
2024-01-18 23:12:58,628] [INFO] file=/usr/lib/python3/dist-packages/pywps/app/Service.py line=310 module=Service function=call Request: execute
2024-01-18 23:12:58,637] [INFO] file=/usr/lib/python3/dist-packages/pywps/validator/complexvalidator.py line=46 module=complexvalidator function=validategml validating GML; Mode: 2
2024-01-18 23:12:58,638] [ERROR] file=/usr/lib/python3/dist-packages/pywps/exceptions.py line=45 module=exceptions function=__init__ Exception: code: 400, description: Input data not valid using mode 2, locator: 
NoneType: None
2024-01-18 23:17:45,354] [INFO] file=/usr/lib/python3/dist-packages/pywps/app/Service.py line=310 module=Service function=call Request: execute
2024-01-18 23:17:45,463] [ERROR] file=/usr/lib/python3/dist-packages/pywps/exceptions.py line=45 module=exceptions function=__init__ Exception: code: 400, description: Could not convert value '10.0]' to format 'float', locator: 
Traceback (most recent call last):
  File "/usr/lib/python3/dist-packages/pywps/inout/literaltypes.py", line 211, in decorator_selector
    return convert(data)
  File "/usr/lib/python3/dist-packages/pywps/inout/literaltypes.py", line 265, in convert_float
    return float(inpt)
ValueError: could not convert string to float: '10.0]'
2024-01-18 23:17:55,124] [INFO] file=/usr/lib/python3/dist-packages/pywps/app/Service.py line=310 module=Service function=call Request: execute
2024-01-18 23:17:55,132] [ERROR] file=/usr/lib/python3/dist-packages/pywps/exceptions.py line=45 module=exceptions function=__init__ Exception: code: 400, description: Could not convert value ''10.0']' to format 'float', locator: 
Traceback (most recent call last):
  File "/usr/lib/python3/dist-packages/pywps/inout/literaltypes.py", line 211, in decorator_selector
    return convert(data)
  File "/usr/lib/python3/dist-packages/pywps/inout/literaltypes.py", line 265, in convert_float
    return float(inpt)
ValueError: could not convert string to float: "'10.0']"
2024-01-18 23:18:05,021] [INFO] file=/usr/lib/python3/dist-packages/pywps/app/Service.py line=310 module=Service function=call Request: execute
2024-01-18 23:18:05,029] [ERROR] file=/usr/lib/python3/dist-packages/pywps/exceptions.py line=45 module=exceptions function=__init__ Exception: code: 400, description: Could not convert value '"10.0"]' to format 'float', locator: 
Traceback (most recent call last):
  File "/usr/lib/python3/dist-packages/pywps/inout/literaltypes.py", line 211, in decorator_selector
    return convert(data)
  File "/usr/lib/python3/dist-packages/pywps/inout/literaltypes.py", line 265, in convert_float
    return float(inpt)
ValueError: could not convert string to float: '"10.0"]'
2024-01-18 23:18:21,505] [INFO] file=/usr/lib/python3/dist-packages/pywps/app/Service.py line=310 module=Service function=call Request: execute
2024-01-18 23:18:21,512] [ERROR] file=/usr/lib/python3/dist-packages/pywps/exceptions.py line=45 module=exceptions function=__init__ Exception: code: 400, description: Could not convert value '10.0.]' to format 'float', locator: 
Traceback (most recent call last):
  File "/usr/lib/python3/dist-packages/pywps/inout/literaltypes.py", line 211, in decorator_selector
    return convert(data)
  File "/usr/lib/python3/dist-packages/pywps/inout/literaltypes.py", line 265, in convert_float
    return float(inpt)
ValueError: could not convert string to float: '10.0.]'
2024-01-18 23:18:26,106] [INFO] file=/usr/lib/python3/dist-packages/pywps/app/Service.py line=310 module=Service function=call Request: execute
2024-01-18 23:18:26,169] [ERROR] file=/usr/lib/python3/dist-packages/pywps/exceptions.py line=45 module=exceptions function=__init__ Exception: code: 400, description: Could not convert value '10.0]' to format 'float', locator: 
Traceback (most recent call last):
  File "/usr/lib/python3/dist-packages/pywps/inout/literaltypes.py", line 211, in decorator_selector
    return convert(data)
  File "/usr/lib/python3/dist-packages/pywps/inout/literaltypes.py", line 265, in convert_float
    return float(inpt)
ValueError: could not convert string to float: '10.0]'
2024-01-18 23:19:18,507] [INFO] file=/usr/lib/python3/dist-packages/pywps/app/Service.py line=310 module=Service function=call Request: execute
2024-01-18 23:19:18,515] [INFO] file=/usr/lib/python3/dist-packages/pywps/validator/complexvalidator.py line=46 module=complexvalidator function=validategml validating GML; Mode: 2
2024-01-18 23:19:18,516] [ERROR] file=/usr/lib/python3/dist-packages/pywps/exceptions.py line=45 module=exceptions function=__init__ Exception: code: 400, description: Input data not valid using mode 2, locator: 
NoneType: None
2024-01-18 23:19:25,807] [INFO] file=/usr/lib/python3/dist-packages/pywps/app/Service.py line=310 module=Service function=call Request: execute
2024-01-18 23:19:25,819] [ERROR] file=/usr/lib/python3/dist-packages/pywps/exceptions.py line=45 module=exceptions function=__init__ Exception: code: 400, description: Could not convert value '10.0]' to format 'float', locator: 
Traceback (most recent call last):
  File "/usr/lib/python3/dist-packages/pywps/inout/literaltypes.py", line 211, in decorator_selector
    return convert(data)
  File "/usr/lib/python3/dist-packages/pywps/inout/literaltypes.py", line 265, in convert_float
    return float(inpt)
ValueError: could not convert string to float: '10.0]'
2024-01-18 23:19:39,671] [INFO] file=/usr/lib/python3/dist-packages/pywps/app/Service.py line=310 module=Service function=call Request: execute
2024-01-18 23:19:39,805] [ERROR] file=/usr/lib/python3/dist-packages/pywps/exceptions.py line=45 module=exceptions function=__init__ Exception: code: 400, description: Could not convert value '10.0]' to format 'float', locator: 
Traceback (most recent call last):
  File "/usr/lib/python3/dist-packages/pywps/inout/literaltypes.py", line 211, in decorator_selector
    return convert(data)
  File "/usr/lib/python3/dist-packages/pywps/inout/literaltypes.py", line 265, in convert_float
    return float(inpt)
ValueError: could not convert string to float: '10.0]'
2024-01-18 23:19:45,619] [INFO] file=/usr/lib/python3/dist-packages/pywps/app/Service.py line=310 module=Service function=call Request: execute
2024-01-18 23:19:45,629] [ERROR] file=/usr/lib/python3/dist-packages/pywps/exceptions.py line=45 module=exceptions function=__init__ Exception: code: 400, description: Could not convert value '10.0      ]' to format 'float', locator: 
Traceback (most recent call last):
  File "/usr/lib/python3/dist-packages/pywps/inout/literaltypes.py", line 211, in decorator_selector
    return convert(data)
  File "/usr/lib/python3/dist-packages/pywps/inout/literaltypes.py", line 265, in convert_float
    return float(inpt)
ValueError: could not convert string to float: '10.0      ]'
2024-01-18 23:20:51,908] [INFO] file=/usr/lib/python3/dist-packages/pywps/app/Service.py line=310 module=Service function=call Request: execute
2024-01-18 23:20:51,943] [ERROR] file=/usr/lib/python3/dist-packages/pywps/exceptions.py line=45 module=exceptions function=__init__ Exception: code: 400, description: Could not convert value '10.0
]' to format 'float', locator: 
Traceback (most recent call last):
  File "/usr/lib/python3/dist-packages/pywps/inout/literaltypes.py", line 211, in decorator_selector
    return convert(data)
  File "/usr/lib/python3/dist-packages/pywps/inout/literaltypes.py", line 265, in convert_float
    return float(inpt)
ValueError: could not convert string to float: '10.0\n]'
2024-01-18 23:21:04,201] [INFO] file=/usr/lib/python3/dist-packages/pywps/app/Service.py line=310 module=Service function=call Request: execute
2024-01-18 23:21:04,243] [ERROR] file=/usr/lib/python3/dist-packages/pywps/exceptions.py line=45 module=exceptions function=__init__ Exception: code: 400, description: Could not convert value '10.0]' to format 'float', locator: 
Traceback (most recent call last):
  File "/usr/lib/python3/dist-packages/pywps/inout/literaltypes.py", line 211, in decorator_selector
    return convert(data)
  File "/usr/lib/python3/dist-packages/pywps/inout/literaltypes.py", line 265, in convert_float
    return float(inpt)
ValueError: could not convert string to float: '10.0]'
2024-01-18 23:21:23,990] [INFO] file=/usr/lib/python3/dist-packages/pywps/app/Service.py line=310 module=Service function=call Request: execute
2024-01-18 23:21:23,999] [ERROR] file=/usr/lib/python3/dist-packages/pywps/exceptions.py line=45 module=exceptions function=__init__ Exception: code: 400, description: Could not convert value '10]' to format 'float', locator: 
Traceback (most recent call last):
  File "/usr/lib/python3/dist-packages/pywps/inout/literaltypes.py", line 211, in decorator_selector
    return convert(data)
  File "/usr/lib/python3/dist-packages/pywps/inout/literaltypes.py", line 265, in convert_float
    return float(inpt)
ValueError: could not convert string to float: '10]'
2024-01-18 23:22:23,308] [INFO] file=/usr/lib/python3/dist-packages/pywps/app/Service.py line=310 module=Service function=call Request: execute
2024-01-18 23:22:23,315] [ERROR] file=/usr/lib/python3/dist-packages/pywps/exceptions.py line=45 module=exceptions function=__init__ Exception: code: 400, description: Could not convert value '10]' to format 'float', locator: 
Traceback (most recent call last):
  File "/usr/lib/python3/dist-packages/pywps/inout/literaltypes.py", line 211, in decorator_selector
    return convert(data)
  File "/usr/lib/python3/dist-packages/pywps/inout/literaltypes.py", line 265, in convert_float
    return float(inpt)
ValueError: could not convert string to float: '10]'
2024-01-18 23:23:33,429] [INFO] file=/usr/lib/python3/dist-packages/pywps/app/Service.py line=310 module=Service function=call Request: describeprocess
2024-01-18 23:26:08,542] [INFO] file=/usr/lib/python3/dist-packages/pywps/app/Service.py line=310 module=Service function=call Request: execute
2024-01-18 23:26:08,550] [INFO] file=/usr/lib/python3/dist-packages/pywps/validator/complexvalidator.py line=46 module=complexvalidator function=validategml validating GML; Mode: 2
2024-01-18 23:26:08,551] [ERROR] file=/usr/lib/python3/dist-packages/pywps/exceptions.py line=45 module=exceptions function=__init__ Exception: code: 400, description: Input data not valid using mode 2, locator: 
NoneType: None
2024-01-18 23:28:16,249] [INFO] file=/usr/lib/python3/dist-packages/pywps/app/Service.py line=310 module=Service function=call Request: execute
2024-01-18 23:28:16,257] [ERROR] file=/usr/lib/python3/dist-packages/pywps/exceptions.py line=45 module=exceptions function=__init__ Exception: code: 400, description: Could not convert value '10]' to format 'float', locator: 
Traceback (most recent call last):
  File "/usr/lib/python3/dist-packages/pywps/inout/literaltypes.py", line 211, in decorator_selector
    return convert(data)
  File "/usr/lib/python3/dist-packages/pywps/inout/literaltypes.py", line 265, in convert_float
    return float(inpt)
ValueError: could not convert string to float: '10]'
2024-01-18 23:31:27,139] [INFO] file=/usr/lib/python3/dist-packages/pywps/app/Service.py line=310 module=Service function=call Request: execute
2024-01-18 23:31:27,148] [ERROR] file=/usr/lib/python3/dist-packages/pywps/exceptions.py line=45 module=exceptions function=__init__ Exception: code: 400, description: Could not convert value '10    ]' to format 'float', locator: 
Traceback (most recent call last):
  File "/usr/lib/python3/dist-packages/pywps/inout/literaltypes.py", line 211, in decorator_selector
    return convert(data)
  File "/usr/lib/python3/dist-packages/pywps/inout/literaltypes.py", line 265, in convert_float
    return float(inpt)
ValueError: could not convert string to float: '10    ]'
2024-01-18 23:31:36,444] [INFO] file=/usr/lib/python3/dist-packages/pywps/app/Service.py line=310 module=Service function=call Request: execute
2024-01-18 23:31:36,453] [ERROR] file=/usr/lib/python3/dist-packages/pywps/exceptions.py line=45 module=exceptions function=__init__ Exception: code: 400, description: Could not convert value '10]' to format 'float', locator: 
Traceback (most recent call last):
  File "/usr/lib/python3/dist-packages/pywps/inout/literaltypes.py", line 211, in decorator_selector
    return convert(data)
  File "/usr/lib/python3/dist-packages/pywps/inout/literaltypes.py", line 265, in convert_float
    return float(inpt)
ValueError: could not convert string to float: '10]'
2024-01-18 23:33:33,815] [INFO] file=/usr/lib/python3/dist-packages/pywps/app/Service.py line=310 module=Service function=call Request: execute
2024-01-18 23:33:33,823] [ERROR] file=/usr/lib/python3/dist-packages/pywps/exceptions.py line=45 module=exceptions function=__init__ Exception: code: 400, description: Could not convert value '10"]' to format 'float', locator: 
Traceback (most recent call last):
  File "/usr/lib/python3/dist-packages/pywps/inout/literaltypes.py", line 211, in decorator_selector
    return convert(data)
  File "/usr/lib/python3/dist-packages/pywps/inout/literaltypes.py", line 265, in convert_float
    return float(inpt)
ValueError: could not convert string to float: '10"]'
2024-01-18 23:36:15,602] [INFO] file=/usr/lib/python3/dist-packages/pywps/app/Service.py line=310 module=Service function=call Request: execute
2024-01-18 23:36:15,610] [ERROR] file=/usr/lib/python3/dist-packages/pywps/exceptions.py line=45 module=exceptions function=__init__ Exception: code: 400, description: Could not convert value '10]' to format 'float', locator: 
Traceback (most recent call last):
  File "/usr/lib/python3/dist-packages/pywps/inout/literaltypes.py", line 211, in decorator_selector
    return convert(data)
  File "/usr/lib/python3/dist-packages/pywps/inout/literaltypes.py", line 265, in convert_float
    return float(inpt)
ValueError: could not convert string to float: '10]'
2024-01-18 23:36:40,631] [INFO] file=/usr/lib/python3/dist-packages/pywps/app/Service.py line=310 module=Service function=call Request: execute
2024-01-18 23:36:40,721] [ERROR] file=/usr/lib/python3/dist-packages/pywps/exceptions.py line=45 module=exceptions function=__init__ Exception: code: 400, description: Could not convert value '10]' to format 'float', locator: 
Traceback (most recent call last):
  File "/usr/lib/python3/dist-packages/pywps/inout/literaltypes.py", line 211, in decorator_selector
    return convert(data)
  File "/usr/lib/python3/dist-packages/pywps/inout/literaltypes.py", line 265, in convert_float
    return float(inpt)
ValueError: could not convert string to float: '10]'
2024-01-18 23:38:05,541] [INFO] file=/usr/lib/python3/dist-packages/pywps/app/Service.py line=310 module=Service function=call Request: execute
2024-01-18 23:38:05,551] [ERROR] file=/usr/lib/python3/dist-packages/pywps/exceptions.py line=45 module=exceptions function=__init__ Exception: code: 400, description: Could not convert value '10]' to format 'float', locator: 
Traceback (most recent call last):
  File "/usr/lib/python3/dist-packages/pywps/inout/literaltypes.py", line 211, in decorator_selector
    return convert(data)
  File "/usr/lib/python3/dist-packages/pywps/inout/literaltypes.py", line 265, in convert_float
    return float(inpt)
ValueError: could not convert string to float: '10]'
2024-01-18 23:38:24,565] [INFO] file=/usr/lib/python3/dist-packages/pywps/app/Service.py line=310 module=Service function=call Request: execute
2024-01-18 23:38:24,651] [ERROR] file=/usr/lib/python3/dist-packages/pywps/exceptions.py line=45 module=exceptions function=__init__ Exception: code: 500, description: No applicable error code, please check error log., locator: 
Traceback (most recent call last):
  File "/usr/lib/python3/dist-packages/pywps/app/Service.py", line 336, in call
    raise e
  File "/usr/lib/python3/dist-packages/pywps/app/Service.py", line 326, in call
    response = self.execute(
  File "/usr/lib/python3/dist-packages/pywps/app/Service.py", line 81, in execute
    return self._parse_and_execute(process, wps_request, uuid)
  File "/usr/lib/python3/dist-packages/pywps/app/Service.py", line 126, in _parse_and_execute
    data_inputs[inpt.identifier] = self.create_literal_inputs(
  File "/usr/lib/python3/dist-packages/pywps/app/Service.py", line 227, in create_literal_inputs
    newinpt.data = inpt.get('data')
  File "/usr/lib/python3/dist-packages/pywps/inout/basic.py", line 541, in data
    DataHandler.data.fset(self, value)
  File "/usr/lib/python3/dist-packages/pywps/inout/basic.py", line 375, in data
    self._check_valid()
  File "/usr/lib/python3/dist-packages/pywps/inout/basic.py", line 167, in _check_valid
    _valid = validate(self, self.valid_mode)
  File "/usr/lib/python3/dist-packages/pywps/validator/literalvalidator.py", line 82, in validate_allowed_values
    passed = _validate_range(value, data)
  File "/usr/lib/python3/dist-packages/pywps/validator/literalvalidator.py", line 112, in _validate_range
    if interval.minval <= data <= interval.maxval:
TypeError: '<=' not supported between instances of 'int' and 'str'
2024-01-18 23:41:33,499] [INFO] file=/usr/lib/python3/dist-packages/pywps/app/Service.py line=310 module=Service function=call Request: execute
2024-01-18 23:41:33,591] [ERROR] file=/usr/lib/python3/dist-packages/pywps/exceptions.py line=45 module=exceptions function=__init__ Exception: code: 500, description: No applicable error code, please check error log., locator: 
Traceback (most recent call last):
  File "/usr/lib/python3/dist-packages/pywps/app/Service.py", line 336, in call
    raise e
  File "/usr/lib/python3/dist-packages/pywps/app/Service.py", line 326, in call
    response = self.execute(
  File "/usr/lib/python3/dist-packages/pywps/app/Service.py", line 81, in execute
    return self._parse_and_execute(process, wps_request, uuid)
  File "/usr/lib/python3/dist-packages/pywps/app/Service.py", line 126, in _parse_and_execute
    data_inputs[inpt.identifier] = self.create_literal_inputs(
  File "/usr/lib/python3/dist-packages/pywps/app/Service.py", line 227, in create_literal_inputs
    newinpt.data = inpt.get('data')
  File "/usr/lib/python3/dist-packages/pywps/inout/basic.py", line 541, in data
    DataHandler.data.fset(self, value)
  File "/usr/lib/python3/dist-packages/pywps/inout/basic.py", line 375, in data
    self._check_valid()
  File "/usr/lib/python3/dist-packages/pywps/inout/basic.py", line 167, in _check_valid
    _valid = validate(self, self.valid_mode)
  File "/usr/lib/python3/dist-packages/pywps/validator/literalvalidator.py", line 82, in validate_allowed_values
    passed = _validate_range(value, data)
  File "/usr/lib/python3/dist-packages/pywps/validator/literalvalidator.py", line 112, in _validate_range
    if interval.minval <= data <= interval.maxval:
TypeError: '<=' not supported between instances of 'int' and 'str'
2024-01-18 23:41:59,687] [INFO] file=/usr/lib/python3/dist-packages/pywps/app/Service.py line=310 module=Service function=call Request: execute
2024-01-18 23:41:59,809] [ERROR] file=/usr/lib/python3/dist-packages/pywps/exceptions.py line=45 module=exceptions function=__init__ Exception: code: 500, description: No applicable error code, please check error log., locator: 
Traceback (most recent call last):
  File "/usr/lib/python3/dist-packages/pywps/app/Service.py", line 336, in call
    raise e
  File "/usr/lib/python3/dist-packages/pywps/app/Service.py", line 326, in call
    response = self.execute(
  File "/usr/lib/python3/dist-packages/pywps/app/Service.py", line 81, in execute
    return self._parse_and_execute(process, wps_request, uuid)
  File "/usr/lib/python3/dist-packages/pywps/app/Service.py", line 126, in _parse_and_execute
    data_inputs[inpt.identifier] = self.create_literal_inputs(
  File "/usr/lib/python3/dist-packages/pywps/app/Service.py", line 227, in create_literal_inputs
    newinpt.data = inpt.get('data')
  File "/usr/lib/python3/dist-packages/pywps/inout/basic.py", line 541, in data
    DataHandler.data.fset(self, value)
  File "/usr/lib/python3/dist-packages/pywps/inout/basic.py", line 375, in data
    self._check_valid()
  File "/usr/lib/python3/dist-packages/pywps/inout/basic.py", line 167, in _check_valid
    _valid = validate(self, self.valid_mode)
  File "/usr/lib/python3/dist-packages/pywps/validator/literalvalidator.py", line 82, in validate_allowed_values
    passed = _validate_range(value, data)
  File "/usr/lib/python3/dist-packages/pywps/validator/literalvalidator.py", line 112, in _validate_range
    if interval.minval <= data <= interval.maxval:
TypeError: '<=' not supported between instances of 'int' and 'str'
2024-01-18 23:43:52,925] [INFO] file=/usr/lib/python3/dist-packages/pywps/app/Service.py line=310 module=Service function=call Request: execute
2024-01-18 23:43:53,012] [ERROR] file=/usr/lib/python3/dist-packages/pywps/exceptions.py line=45 module=exceptions function=__init__ Exception: code: 400, description: Could not convert value '1]' to format 'float', locator: 
Traceback (most recent call last):
  File "/usr/lib/python3/dist-packages/pywps/inout/literaltypes.py", line 211, in decorator_selector
    return convert(data)
  File "/usr/lib/python3/dist-packages/pywps/inout/literaltypes.py", line 265, in convert_float
    return float(inpt)
ValueError: could not convert string to float: '1]'
2024-01-18 23:44:47,894] [INFO] file=/usr/lib/python3/dist-packages/pywps/app/Service.py line=310 module=Service function=call Request: execute
2024-01-18 23:44:47,974] [ERROR] file=/usr/lib/python3/dist-packages/pywps/exceptions.py line=45 module=exceptions function=__init__ Exception: code: 500, description: No applicable error code, please check error log., locator: 
Traceback (most recent call last):
  File "/usr/lib/python3/dist-packages/pywps/app/Service.py", line 336, in call
    raise e
  File "/usr/lib/python3/dist-packages/pywps/app/Service.py", line 326, in call
    response = self.execute(
  File "/usr/lib/python3/dist-packages/pywps/app/Service.py", line 81, in execute
    return self._parse_and_execute(process, wps_request, uuid)
  File "/usr/lib/python3/dist-packages/pywps/app/Service.py", line 126, in _parse_and_execute
    data_inputs[inpt.identifier] = self.create_literal_inputs(
  File "/usr/lib/python3/dist-packages/pywps/app/Service.py", line 227, in create_literal_inputs
    newinpt.data = inpt.get('data')
  File "/usr/lib/python3/dist-packages/pywps/inout/basic.py", line 541, in data
    DataHandler.data.fset(self, value)
  File "/usr/lib/python3/dist-packages/pywps/inout/basic.py", line 375, in data
    self._check_valid()
  File "/usr/lib/python3/dist-packages/pywps/inout/basic.py", line 167, in _check_valid
    _valid = validate(self, self.valid_mode)
  File "/usr/lib/python3/dist-packages/pywps/validator/literalvalidator.py", line 82, in validate_allowed_values
    passed = _validate_range(value, data)
  File "/usr/lib/python3/dist-packages/pywps/validator/literalvalidator.py", line 112, in _validate_range
    if interval.minval <= data <= interval.maxval:
TypeError: '<=' not supported between instances of 'int' and 'str'
2024-01-18 23:45:49,168] [INFO] file=/usr/lib/python3/dist-packages/pywps/app/Service.py line=310 module=Service function=call Request: execute
2024-01-18 23:45:49,247] [ERROR] file=/usr/lib/python3/dist-packages/pywps/exceptions.py line=45 module=exceptions function=__init__ Exception: code: 500, description: No applicable error code, please check error log., locator: 
Traceback (most recent call last):
  File "/usr/lib/python3/dist-packages/pywps/app/Service.py", line 336, in call
    raise e
  File "/usr/lib/python3/dist-packages/pywps/app/Service.py", line 326, in call
    response = self.execute(
  File "/usr/lib/python3/dist-packages/pywps/app/Service.py", line 81, in execute
    return self._parse_and_execute(process, wps_request, uuid)
  File "/usr/lib/python3/dist-packages/pywps/app/Service.py", line 126, in _parse_and_execute
    data_inputs[inpt.identifier] = self.create_literal_inputs(
  File "/usr/lib/python3/dist-packages/pywps/app/Service.py", line 227, in create_literal_inputs
    newinpt.data = inpt.get('data')
  File "/usr/lib/python3/dist-packages/pywps/inout/basic.py", line 541, in data
    DataHandler.data.fset(self, value)
  File "/usr/lib/python3/dist-packages/pywps/inout/basic.py", line 375, in data
    self._check_valid()
  File "/usr/lib/python3/dist-packages/pywps/inout/basic.py", line 167, in _check_valid
    _valid = validate(self, self.valid_mode)
  File "/usr/lib/python3/dist-packages/pywps/validator/literalvalidator.py", line 82, in validate_allowed_values
    passed = _validate_range(value, data)
  File "/usr/lib/python3/dist-packages/pywps/validator/literalvalidator.py", line 112, in _validate_range
    if interval.minval <= data <= interval.maxval:
TypeError: '<=' not supported between instances of 'int' and 'str'
2024-01-18 23:49:57,038] [INFO] file=/usr/lib/python3/dist-packages/pywps/app/Service.py line=310 module=Service function=call Request: execute
2024-01-18 23:49:57,104] [ERROR] file=/usr/lib/python3/dist-packages/pywps/exceptions.py line=45 module=exceptions function=__init__ Exception: code: 400, description: Could not convert value '1]' to format 'float', locator: 
Traceback (most recent call last):
  File "/usr/lib/python3/dist-packages/pywps/inout/literaltypes.py", line 211, in decorator_selector
    return convert(data)
  File "/usr/lib/python3/dist-packages/pywps/inout/literaltypes.py", line 265, in convert_float
    return float(inpt)
ValueError: could not convert string to float: '1]'
2024-01-19 10:22:38,947] [INFO] file=/usr/lib/python3/dist-packages/pywps/app/Service.py line=310 module=Service function=call Request: execute
2024-01-19 10:22:39,229] [ERROR] file=/usr/lib/python3/dist-packages/pywps/exceptions.py line=45 module=exceptions function=__init__ Exception: code: 400, description: Could not convert value '1]' to format 'float', locator: 
Traceback (most recent call last):
  File "/usr/lib/python3/dist-packages/pywps/inout/literaltypes.py", line 211, in decorator_selector
    return convert(data)
  File "/usr/lib/python3/dist-packages/pywps/inout/literaltypes.py", line 265, in convert_float
    return float(inpt)
ValueError: could not convert string to float: '1]'
